2024-05-27 06:27:25 | INFO    | __main__:stash:131 | run - {'image': '20231121', 'version': '0.10.1.post2', 'role': 'EpicPlayer', 'headless': True}
2024-05-27 06:27:33 | WARNING    | epic_games.agent:get_order_history:467 | Failed to get order history, cookie may have expired - {}
2024-05-27 06:27:33 | DEBUG    | __main__:create_tasks:66 | Put task - {'title': 'Farming Simulator 22', 'url': 'https://store.epicgames.com/en-US/p/farming-simulator-22'}
2024-05-27 06:27:38 | INFO    | epic_games.agent:claim_weekly_games:294 | claim_weekly_games - {'action': 'go to store', 'url': 'https://store.epicgames.com/en-US/p/farming-simulator-22'}
2024-05-27 06:27:48 | INFO    | epic_games.agent:claim_weekly_games:326 | claim_weekly_games - {'action': 'move to webPurchaseContainer iframe'}
2024-05-27 06:27:50 | INFO    | epic_games.agent:claim_weekly_games:328 | claim_weekly_games - {'action': 'click payment button'}
2024-05-27 06:27:51 | ERROR    | hcaptcha_challenger.agents.playwright.control:handler:153 | 'utf-8' codec can't decode byte 0x81 in position 2: invalid start byte - {}
Traceback (most recent call last):
  File "/home/runner/work/epic_/epic_/epic/src/claim.py", line 162, in <module>
    asyncio.run(run())
  File "/opt/hostedtoolcache/Python/3.10.14/x64/lib/python3.10/asyncio/runners.py", line 44, in run
    return loop.run_until_complete(main)
  File "/opt/hostedtoolcache/Python/3.10.14/x64/lib/python3.10/asyncio/base_events.py", line 636, in run_until_complete
    self.run_forever()
  File "/opt/hostedtoolcache/Python/3.10.14/x64/lib/python3.10/asyncio/base_events.py", line 603, in run_forever
    self._run_once()
  File "/opt/hostedtoolcache/Python/3.10.14/x64/lib/python3.10/asyncio/base_events.py", line 1909, in _run_once
    handle._run()
  File "/opt/hostedtoolcache/Python/3.10.14/x64/lib/python3.10/asyncio/events.py", line 80, in _run
    self._context.run(self._callback, *self._args)
> File "/opt/hostedtoolcache/Python/3.10.14/x64/lib/python3.10/site-packages/hcaptcha_challenger/agents/playwright/control.py", line 145, in handler
    data = await response.json()
  File "/opt/hostedtoolcache/Python/3.10.14/x64/lib/python3.10/site-packages/playwright/async_api/_generated.py", line 614, in json
    return mapping.from_maybe_impl(await self._impl_obj.json())
  File "/opt/hostedtoolcache/Python/3.10.14/x64/lib/python3.10/site-packages/playwright/_impl/_network.py", line 613, in json
    return json.loads(await self.text())
  File "/opt/hostedtoolcache/Python/3.10.14/x64/lib/python3.10/site-packages/playwright/_impl/_network.py", line 610, in text
    return content.decode()
UnicodeDecodeError: 'utf-8' codec can't decode byte 0x81 in position 2: invalid start byte
2024-05-27 06:28:25 | ERROR    | hcaptcha_challenger.agents.playwright.control:execute:615 | task interrupt <backcall> - {'reason': 'Failed to obtain challenge task'}
2024-05-27 06:28:25 | DEBUG    | epic_games.agent:insert_challenge:106 | task done - {'sattus': 'success'}
2024-05-27 06:28:27 | ERROR    | hcaptcha_challenger.agents.playwright.control:handler:153 | 'utf-8' codec can't decode byte 0x8e in position 0: invalid start byte - {}
Traceback (most recent call last):
  File "/home/runner/work/epic_/epic_/epic/src/claim.py", line 162, in <module>
    asyncio.run(run())
  File "/opt/hostedtoolcache/Python/3.10.14/x64/lib/python3.10/asyncio/runners.py", line 44, in run
    return loop.run_until_complete(main)
  File "/opt/hostedtoolcache/Python/3.10.14/x64/lib/python3.10/asyncio/base_events.py", line 636, in run_until_complete
    self.run_forever()
  File "/opt/hostedtoolcache/Python/3.10.14/x64/lib/python3.10/asyncio/base_events.py", line 603, in run_forever
    self._run_once()
  File "/opt/hostedtoolcache/Python/3.10.14/x64/lib/python3.10/asyncio/base_events.py", line 1909, in _run_once
    handle._run()
  File "/opt/hostedtoolcache/Python/3.10.14/x64/lib/python3.10/asyncio/events.py", line 80, in _run
    self._context.run(self._callback, *self._args)
> File "/opt/hostedtoolcache/Python/3.10.14/x64/lib/python3.10/site-packages/hcaptcha_challenger/agents/playwright/control.py", line 145, in handler
    data = await response.json()
  File "/opt/hostedtoolcache/Python/3.10.14/x64/lib/python3.10/site-packages/playwright/async_api/_generated.py", line 614, in json
    return mapping.from_maybe_impl(await self._impl_obj.json())
  File "/opt/hostedtoolcache/Python/3.10.14/x64/lib/python3.10/site-packages/playwright/_impl/_network.py", line 613, in json
    return json.loads(await self.text())
  File "/opt/hostedtoolcache/Python/3.10.14/x64/lib/python3.10/site-packages/playwright/_impl/_network.py", line 610, in text
    return content.decode()
UnicodeDecodeError: 'utf-8' codec can't decode byte 0x8e in position 0: invalid start byte
2024-05-27 06:28:57 | INFO    | epic_games.agent:claim_weekly_games:294 | claim_weekly_games - {'action': 'go to store', 'url': 'https://store.epicgames.com/en-US/p/farming-simulator-22'}
2024-05-27 06:29:07 | INFO    | epic_games.agent:claim_weekly_games:326 | claim_weekly_games - {'action': 'move to webPurchaseContainer iframe'}
2024-05-27 06:29:09 | INFO    | epic_games.agent:claim_weekly_games:328 | claim_weekly_games - {'action': 'click payment button'}
2024-05-27 06:29:10 | ERROR    | hcaptcha_challenger.agents.playwright.control:handler:153 | 'utf-8' codec can't decode byte 0xab in position 1: invalid start byte - {}
Traceback (most recent call last):
  File "/home/runner/work/epic_/epic_/epic/src/claim.py", line 162, in <module>
    asyncio.run(run())
  File "/opt/hostedtoolcache/Python/3.10.14/x64/lib/python3.10/asyncio/runners.py", line 44, in run
    return loop.run_until_complete(main)
  File "/opt/hostedtoolcache/Python/3.10.14/x64/lib/python3.10/asyncio/base_events.py", line 636, in run_until_complete
    self.run_forever()
  File "/opt/hostedtoolcache/Python/3.10.14/x64/lib/python3.10/asyncio/base_events.py", line 603, in run_forever
    self._run_once()
  File "/opt/hostedtoolcache/Python/3.10.14/x64/lib/python3.10/asyncio/base_events.py", line 1909, in _run_once
    handle._run()
  File "/opt/hostedtoolcache/Python/3.10.14/x64/lib/python3.10/asyncio/events.py", line 80, in _run
    self._context.run(self._callback, *self._args)
> File "/opt/hostedtoolcache/Python/3.10.14/x64/lib/python3.10/site-packages/hcaptcha_challenger/agents/playwright/control.py", line 145, in handler
    data = await response.json()
  File "/opt/hostedtoolcache/Python/3.10.14/x64/lib/python3.10/site-packages/playwright/async_api/_generated.py", line 614, in json
    return mapping.from_maybe_impl(await self._impl_obj.json())
  File "/opt/hostedtoolcache/Python/3.10.14/x64/lib/python3.10/site-packages/playwright/_impl/_network.py", line 613, in json
    return json.loads(await self.text())
  File "/opt/hostedtoolcache/Python/3.10.14/x64/lib/python3.10/site-packages/playwright/_impl/_network.py", line 610, in text
    return content.decode()
UnicodeDecodeError: 'utf-8' codec can't decode byte 0xab in position 1: invalid start byte
2024-05-27 06:29:44 | ERROR    | hcaptcha_challenger.agents.playwright.control:execute:615 | task interrupt <backcall> - {'reason': 'Failed to obtain challenge task'}
2024-05-27 06:29:44 | DEBUG    | epic_games.agent:insert_challenge:106 | task done - {'sattus': 'success'}
2024-05-27 06:29:46 | ERROR    | hcaptcha_challenger.agents.playwright.control:handler:153 | 'utf-8' codec can't decode byte 0xe6 in position 0: invalid continuation byte - {}
Traceback (most recent call last):
  File "/home/runner/work/epic_/epic_/epic/src/claim.py", line 162, in <module>
    asyncio.run(run())
  File "/opt/hostedtoolcache/Python/3.10.14/x64/lib/python3.10/asyncio/runners.py", line 44, in run
    return loop.run_until_complete(main)
  File "/opt/hostedtoolcache/Python/3.10.14/x64/lib/python3.10/asyncio/base_events.py", line 636, in run_until_complete
    self.run_forever()
  File "/opt/hostedtoolcache/Python/3.10.14/x64/lib/python3.10/asyncio/base_events.py", line 603, in run_forever
    self._run_once()
  File "/opt/hostedtoolcache/Python/3.10.14/x64/lib/python3.10/asyncio/base_events.py", line 1909, in _run_once
    handle._run()
  File "/opt/hostedtoolcache/Python/3.10.14/x64/lib/python3.10/asyncio/events.py", line 80, in _run
    self._context.run(self._callback, *self._args)
> File "/opt/hostedtoolcache/Python/3.10.14/x64/lib/python3.10/site-packages/hcaptcha_challenger/agents/playwright/control.py", line 145, in handler
    data = await response.json()
  File "/opt/hostedtoolcache/Python/3.10.14/x64/lib/python3.10/site-packages/playwright/async_api/_generated.py", line 614, in json
    return mapping.from_maybe_impl(await self._impl_obj.json())
  File "/opt/hostedtoolcache/Python/3.10.14/x64/lib/python3.10/site-packages/playwright/_impl/_network.py", line 613, in json
    return json.loads(await self.text())
  File "/opt/hostedtoolcache/Python/3.10.14/x64/lib/python3.10/site-packages/playwright/_impl/_network.py", line 610, in text
    return content.decode()
UnicodeDecodeError: 'utf-8' codec can't decode byte 0xe6 in position 0: invalid continuation byte
2024-05-27 06:30:16 | INFO    | epic_games.agent:claim_weekly_games:294 | claim_weekly_games - {'action': 'go to store', 'url': 'https://store.epicgames.com/en-US/p/farming-simulator-22'}
2024-05-27 06:30:26 | INFO    | epic_games.agent:claim_weekly_games:326 | claim_weekly_games - {'action': 'move to webPurchaseContainer iframe'}
2024-05-27 06:30:28 | INFO    | epic_games.agent:claim_weekly_games:328 | claim_weekly_games - {'action': 'click payment button'}
2024-05-27 06:30:29 | ERROR    | hcaptcha_challenger.agents.playwright.control:handler:153 | 'utf-8' codec can't decode byte 0xa4 in position 1: invalid start byte - {}
Traceback (most recent call last):
  File "/home/runner/work/epic_/epic_/epic/src/claim.py", line 162, in <module>
    asyncio.run(run())
  File "/opt/hostedtoolcache/Python/3.10.14/x64/lib/python3.10/asyncio/runners.py", line 44, in run
    return loop.run_until_complete(main)
  File "/opt/hostedtoolcache/Python/3.10.14/x64/lib/python3.10/asyncio/base_events.py", line 636, in run_until_complete
    self.run_forever()
  File "/opt/hostedtoolcache/Python/3.10.14/x64/lib/python3.10/asyncio/base_events.py", line 603, in run_forever
    self._run_once()
  File "/opt/hostedtoolcache/Python/3.10.14/x64/lib/python3.10/asyncio/base_events.py", line 1909, in _run_once
    handle._run()
  File "/opt/hostedtoolcache/Python/3.10.14/x64/lib/python3.10/asyncio/events.py", line 80, in _run
    self._context.run(self._callback, *self._args)
> File "/opt/hostedtoolcache/Python/3.10.14/x64/lib/python3.10/site-packages/hcaptcha_challenger/agents/playwright/control.py", line 145, in handler
    data = await response.json()
  File "/opt/hostedtoolcache/Python/3.10.14/x64/lib/python3.10/site-packages/playwright/async_api/_generated.py", line 614, in json
    return mapping.from_maybe_impl(await self._impl_obj.json())
  File "/opt/hostedtoolcache/Python/3.10.14/x64/lib/python3.10/site-packages/playwright/_impl/_network.py", line 613, in json
    return json.loads(await self.text())
  File "/opt/hostedtoolcache/Python/3.10.14/x64/lib/python3.10/site-packages/playwright/_impl/_network.py", line 610, in text
    return content.decode()
UnicodeDecodeError: 'utf-8' codec can't decode byte 0xa4 in position 1: invalid start byte
2024-05-27 06:31:03 | ERROR    | hcaptcha_challenger.agents.playwright.control:execute:615 | task interrupt <backcall> - {'reason': 'Failed to obtain challenge task'}
2024-05-27 06:31:03 | DEBUG    | epic_games.agent:insert_challenge:106 | task done - {'sattus': 'success'}
2024-05-27 06:31:05 | ERROR    | hcaptcha_challenger.agents.playwright.control:handler:153 | 'utf-8' codec can't decode byte 0xa3 in position 2: invalid start byte - {}
Traceback (most recent call last):
  File "/home/runner/work/epic_/epic_/epic/src/claim.py", line 162, in <module>
    asyncio.run(run())
  File "/opt/hostedtoolcache/Python/3.10.14/x64/lib/python3.10/asyncio/runners.py", line 44, in run
    return loop.run_until_complete(main)
  File "/opt/hostedtoolcache/Python/3.10.14/x64/lib/python3.10/asyncio/base_events.py", line 636, in run_until_complete
    self.run_forever()
  File "/opt/hostedtoolcache/Python/3.10.14/x64/lib/python3.10/asyncio/base_events.py", line 603, in run_forever
    self._run_once()
  File "/opt/hostedtoolcache/Python/3.10.14/x64/lib/python3.10/asyncio/base_events.py", line 1909, in _run_once
    handle._run()
  File "/opt/hostedtoolcache/Python/3.10.14/x64/lib/python3.10/asyncio/events.py", line 80, in _run
    self._context.run(self._callback, *self._args)
> File "/opt/hostedtoolcache/Python/3.10.14/x64/lib/python3.10/site-packages/hcaptcha_challenger/agents/playwright/control.py", line 145, in handler
    data = await response.json()
  File "/opt/hostedtoolcache/Python/3.10.14/x64/lib/python3.10/site-packages/playwright/async_api/_generated.py", line 614, in json
    return mapping.from_maybe_impl(await self._impl_obj.json())
  File "/opt/hostedtoolcache/Python/3.10.14/x64/lib/python3.10/site-packages/playwright/_impl/_network.py", line 613, in json
    return json.loads(await self.text())
  File "/opt/hostedtoolcache/Python/3.10.14/x64/lib/python3.10/site-packages/playwright/_impl/_network.py", line 610, in text
    return content.decode()
UnicodeDecodeError: 'utf-8' codec can't decode byte 0xa3 in position 2: invalid start byte
2024-05-27 06:31:35 | ERROR    | __main__:run:158 | An error has been caught in function 'run', process 'MainProcess' (3749), thread 'MainThread' (139825325800320): - {}
Traceback (most recent call last):
  File "/home/runner/work/epic_/epic_/epic/src/claim.py", line 162, in <module>
    asyncio.run(run())
  File "/opt/hostedtoolcache/Python/3.10.14/x64/lib/python3.10/asyncio/runners.py", line 44, in run
    return loop.run_until_complete(main)
  File "/opt/hostedtoolcache/Python/3.10.14/x64/lib/python3.10/asyncio/base_events.py", line 636, in run_until_complete
    self.run_forever()
  File "/opt/hostedtoolcache/Python/3.10.14/x64/lib/python3.10/asyncio/base_events.py", line 603, in run_forever
    self._run_once()
  File "/opt/hostedtoolcache/Python/3.10.14/x64/lib/python3.10/asyncio/base_events.py", line 1909, in _run_once
    handle._run()
  File "/opt/hostedtoolcache/Python/3.10.14/x64/lib/python3.10/asyncio/events.py", line 80, in _run
    self._context.run(self._callback, *self._args)
> File "/home/runner/work/epic_/epic_/epic/src/claim.py", line 158, in run
    await agent.stash()
  File "/home/runner/work/epic_/epic_/epic/src/claim.py", line 151, in stash
    await self.claim_epic_games(context)
  File "/home/runner/work/epic_/epic_/epic/src/claim.py", line 122, in claim_epic_games
    await epic.claim_weekly_games(page, single_promotions)
  File "/opt/hostedtoolcache/Python/3.10.14/x64/lib/python3.10/site-packages/tenacity/_asyncio.py", line 142, in async_wrapped
    return await fn(*args, **kwargs)
  File "/opt/hostedtoolcache/Python/3.10.14/x64/lib/python3.10/site-packages/tenacity/_asyncio.py", line 58, in __call__
    do = await self.iter(retry_state=retry_state)
  File "/opt/hostedtoolcache/Python/3.10.14/x64/lib/python3.10/site-packages/tenacity/_asyncio.py", line 110, in iter
    result = await action(retry_state)
  File "/opt/hostedtoolcache/Python/3.10.14/x64/lib/python3.10/site-packages/tenacity/_asyncio.py", line 78, in inner
    return fn(*args, **kwargs)
  File "/opt/hostedtoolcache/Python/3.10.14/x64/lib/python3.10/site-packages/tenacity/__init__.py", line 410, in exc_check
    raise retry_exc.reraise()
  File "/opt/hostedtoolcache/Python/3.10.14/x64/lib/python3.10/site-packages/tenacity/__init__.py", line 183, in reraise
    raise self.last_attempt.result()
  File "/opt/hostedtoolcache/Python/3.10.14/x64/lib/python3.10/concurrent/futures/_base.py", line 451, in result
    return self.__get_result()
  File "/opt/hostedtoolcache/Python/3.10.14/x64/lib/python3.10/concurrent/futures/_base.py", line 403, in __get_result
    raise self._exception
  File "/opt/hostedtoolcache/Python/3.10.14/x64/lib/python3.10/site-packages/tenacity/_asyncio.py", line 61, in __call__
    result = await fn(*args, **kwargs)
  File "/home/runner/work/epic_/epic_/epic/src/epic_games/agent.py", line 338, in claim_weekly_games
    await page.wait_for_url(recur_url)
  File "/opt/hostedtoolcache/Python/3.10.14/x64/lib/python3.10/site-packages/playwright/async_api/_generated.py", line 8798, in wait_for_url
    await self._impl_obj.wait_for_url(
  File "/opt/hostedtoolcache/Python/3.10.14/x64/lib/python3.10/site-packages/playwright/_impl/_page.py", line 543, in wait_for_url
    return await self._main_frame.wait_for_url(**locals_to_params(locals()))
  File "/opt/hostedtoolcache/Python/3.10.14/x64/lib/python3.10/site-packages/playwright/_impl/_frame.py", line 233, in wait_for_url
    async with self.expect_navigation(
  File "/opt/hostedtoolcache/Python/3.10.14/x64/lib/python3.10/site-packages/playwright/_impl/_event_context_manager.py", line 33, in __aexit__
    await self._future
  File "/opt/hostedtoolcache/Python/3.10.14/x64/lib/python3.10/site-packages/playwright/_impl/_frame.py", line 208, in continuation
    event = await waiter.result()
playwright._impl._errors.TimeoutError: Timeout 30000ms exceeded.
=========================== logs ===========================
waiting for navigation to "https://store.epicgames.com/en-US/cart/success" until 'load'
============================================================
